---
layout: article
title: 一些没有归类的杂七杂八知识
---

- scp通过跳板机；

  ```shell
  # -o 指定跳板机 -r递归上传整个目录
  $ scp -o 'ProxyJump bsy@222.195.68.198:50000' -r llm bsy@192.168.1.52:/data/bsy
  ```


- Faiss的IVF index可以使用nprobe max_codes来设置初始的参数:

  nprobe: 每次search搜索的倒排表的数量;

  max_codes: 倒排表中每个倒排表(聚类中心)最多存储的向量的个数，当有新的向量需要存储进这个倒排表并且这个倒排表中已经存储了max_codes个向量时，Faiss会舍弃现有的向量或替换现有的向量

- 在写PPT之前需要想清楚这一页要讲什么

- 无法下载pyworld: 

  **Could not build wheels for pyworld, which is required to install pyproject.toml-based projects**

  ```shell
  $ pip3 install --upgrade setuptools wheel
  $ pip3 install --upgrade pip
  $ sudo apt-get install build-essential
  $ pip install pyproject.toml
  ```

- 启动vllm端:

  ```shell
  $ CUDA_VISIBLE_DEVICES=2,3 python -m vllm.entrypoints.openai.api_server --model tiiuae/falcon-rw-7b --tensor-parallel-size 2 --dtype=float16
  ```

- raise DataNotMatchException(message=ExceptionsMessage.DataTypeInconsistent) from e
  pymilvus.exceptions.DataNotMatchException: <DataNotMatchException: (code=1, message=The data in the same column must be of the same type.)>

- RPC error: [batch_insert], <DataNotMatchException: (code=1, message=The data in the same column must be of the same type.)>, <Time:{'RPC start': '2023-12-12 13:05:09.801796', 'RPC error': '2023-12-12 13:05:09.804880'}>
  Failed to insert batch starting at entity: 24000/150602
  
- Unexpected error: [batch_insert], <class 'UnicodeEncodeError'> returned a result with an exception set, <Time: {'RPC start': '2023-12-13 06:18:26.484665', 'Exception': '2023-12-13 06:18:26.487461'}>
  Failed to insert batch starting at entity: 1000/69888
  Traceback (most recent call last):
    File "/opt/conda/lib/python3.10/site-packages/pymilvus/decorators.py", line 125, in handler
      return func(*args, **kwargs)
    File "/opt/conda/lib/python3.10/site-packages/pymilvus/decorators.py", line 164, in handler
      return func(self, *args, **kwargs)
    File "/opt/conda/lib/python3.10/site-packages/pymilvus/decorators.py", line 106, in handler
      raise e from e
    File "/opt/conda/lib/python3.10/site-packages/pymilvus/decorators.py", line 68, in handler
      return func(*args, **kwargs)
    File "/opt/conda/lib/python3.10/site-packages/pymilvus/client/grpc_handler.py", line 578, in batch_insert
      raise err from err
    File "/opt/conda/lib/python3.10/site-packages/pymilvus/client/grpc_handler.py", line 557, in batch_insert
      request = self._prepare_batch_insert_request(
    File "/opt/conda/lib/python3.10/site-packages/pymilvus/client/grpc_handler.py", line 541, in _prepare_batch_insert_request
      else Prepare.batch_insert_param(collection_name, entities, partition_name, fields_info)
    File "/opt/conda/lib/python3.10/site-packages/pymilvus/client/prepare.py", line 521, in batch_insert_param
      return cls._parse_batch_request(request, entities, fields_info, location)
    File "/opt/conda/lib/python3.10/site-packages/pymilvus/client/prepare.py", line 497, in _parse_batch_request
      field_data = entity_helper.entity_to_field_data(
    File "/opt/conda/lib/python3.10/site-packages/pymilvus/client/entity_helper.py", line 163, in entity_to_field_data
      field_data.scalars.string_data.data.extend(
  SystemError: <class 'UnicodeEncodeError'> returned a result with an exception set
  
  The above exception was the direct cause of the following exception:
  
  Traceback (most recent call last):
    File "/data/llm-app/demo/build_pdf.py", line 63, in <module>
      vectorstore = Milvus.from_documents(
    File "/opt/conda/lib/python3.10/site-packages/langchain/schema/vectorstore.py", line 510, in from_documents
      return cls.from_texts(texts, embedding, metadatas=metadatas, **kwargs)
    File "/opt/conda/lib/python3.10/site-packages/langchain/vectorstores/milvus.py", line 828, in from_texts
      vector_db.add_texts(texts=texts, metadatas=metadatas)
    File "/opt/conda/lib/python3.10/site-packages/langchain/vectorstores/milvus.py", line 474, in add_texts
      raise e
    File "/opt/conda/lib/python3.10/site-packages/langchain/vectorstores/milvus.py", line 468, in add_texts
      res = self.col.insert(insert_list, timeout=timeout, **kwargs)
    File "/opt/conda/lib/python3.10/site-packages/pymilvus/orm/collection.py", line 498, in insert
      res = conn.batch_insert(
    File "/opt/conda/lib/python3.10/site-packages/pymilvus/decorators.py", line 147, in handler
      raise MilvusException(message=f"Unexpected error, message=<{e!s}>") from e
  pymilvus.exceptions.MilvusException: <MilvusException: (code=1, message=Unexpected error, message=<<class 'UnicodeEncodeError'> returned a result with an exception set>)>
  root@4ae9f1f1508f:/data/llm-app/demo# python3 build_pdf.py 
  69888
  Unexpected error: [batch_insert], <class 'UnicodeEncodeError'> returned a result with an exception set, <Time: {'RPC start': '2023-12-13 06:47:03.643230', 'Exception': '2023-12-13 06:47:03.646155'}>
  Failed to insert batch starting at entity: 1000/69888
  Traceback (most recent call last):
    File "/opt/conda/lib/python3.10/site-packages/pymilvus/decorators.py", line 125, in handler
      return func(*args, **kwargs)
    File "/opt/conda/lib/python3.10/site-packages/pymilvus/decorators.py", line 164, in handler
      return func(self, *args, **kwargs)
    File "/opt/conda/lib/python3.10/site-packages/pymilvus/decorators.py", line 106, in handler
      raise e from e
    File "/opt/conda/lib/python3.10/site-packages/pymilvus/decorators.py", line 68, in handler
      return func(*args, **kwargs)
    File "/opt/conda/lib/python3.10/site-packages/pymilvus/client/grpc_handler.py", line 578, in batch_insert
      raise err from err
    File "/opt/conda/lib/python3.10/site-packages/pymilvus/client/grpc_handler.py", line 557, in batch_insert
      request = self._prepare_batch_insert_request(
    File "/opt/conda/lib/python3.10/site-packages/pymilvus/client/grpc_handler.py", line 541, in _prepare_batch_insert_request
      else Prepare.batch_insert_param(collection_name, entities, partition_name, fields_info)
    File "/opt/conda/lib/python3.10/site-packages/pymilvus/client/prepare.py", line 521, in batch_insert_param
      return cls._parse_batch_request(request, entities, fields_info, location)
    File "/opt/conda/lib/python3.10/site-packages/pymilvus/client/prepare.py", line 497, in _parse_batch_request
      field_data = entity_helper.entity_to_field_data(
    File "/opt/conda/lib/python3.10/site-packages/pymilvus/client/entity_helper.py", line 163, in entity_to_field_data
      field_data.scalars.string_data.data.extend(
  SystemError: <class 'UnicodeEncodeError'> returned a result with an exception set
  
  The above exception was the direct cause of the following exception:
  
  Traceback (most recent call last):
    File "/data/llm-app/demo/build_pdf.py", line 63, in <module>
      vectorstore = Milvus.from_documents(
    File "/opt/conda/lib/python3.10/site-packages/langchain/schema/vectorstore.py", line 510, in from_documents
      return cls.from_texts(texts, embedding, metadatas=metadatas, **kwargs)
    File "/opt/conda/lib/python3.10/site-packages/langchain/vectorstores/milvus.py", line 828, in from_texts
      vector_db.add_texts(texts=texts, metadatas=metadatas)
    File "/opt/conda/lib/python3.10/site-packages/langchain/vectorstores/milvus.py", line 474, in add_texts
      raise e
    File "/opt/conda/lib/python3.10/site-packages/langchain/vectorstores/milvus.py", line 468, in add_texts
      res = self.col.insert(insert_list, timeout=timeout, **kwargs)
    File "/opt/conda/lib/python3.10/site-packages/pymilvus/orm/collection.py", line 498, in insert
      res = conn.batch_insert(
    File "/opt/conda/lib/python3.10/site-packages/pymilvus/decorators.py", line 147, in handler
      raise MilvusException(message=f"Unexpected error, message=<{e!s}>") from e
  pymilvus.exceptions.MilvusException: <MilvusException: (code=1, message=Unexpected error, message=<<class 'UnicodeEncodeError'> returned a result with an exception set>)>
  
- Failed to insert batch starting at entity: 1000/3579

- vscode无法打开 : 报错

  [0511/161059.371:ERROR:icu_util.cc(240)] Invalid file descriptor to ICU data received.
  [0511/162430.031:FATAL:v8_initializer.cc(581)] Error loading V8 startup snapshot file

  [When i trying to open VScode by .code command in window 11 , then getting this error - Stack Overflow](https://stackoverflow.com/questions/75341924/when-i-trying-to-open-vscode-by-code-command-in-window-11-then-getting-this-e)

  I had the same issue here. I don´t know why, but after the latest VS Code release, a folder was created in my VS Code folder (C:\Users\XXX\AppData\Local\Programs\Microsoft VS Code) **called "_"**. I copied everything from this folder and pasted it into the VS Code folder and the error disappeared. Try this too and see if solves the problem

  看起来似乎是由于 vscode 版本更新导致有一部分数据被装到了 **"_"** 文件夹中让 vscode无法检索到它导致的，把其中的内容粘贴到主文件夹中即可。

- 在linux下安装.whl包出现错误 : is not a supported wheel on this platform 

  - 安装的包 : draftretriever-0.1.0-cp39-cp39-manylinux_2_34_x86_64.whl

  - 出现错误原因 : 所安装包的名称不符合所在的平台的安装whl的**名称规范**

  - 解决方法 : 输入

    `python -m pip debug --verbose`

    查看所在平台支持的名称规范，比如我这里看到:

    ```
      cp39-cp39-manylinux_2_31_x86_64
      cp39-cp39-manylinux_2_30_x86_64
      cp39-cp39-manylinux_2_29_x86_64
      cp39-cp39-manylinux_2_28_x86_64
      cp39-cp39-manylinux_2_27_x86_64
      cp39-cp39-manylinux_2_26_x86_64
      cp39-cp39-manylinux_2_25_x86_64
      cp39-cp39-manylinux_2_24_x86_64
      cp39-cp39-manylinux_2_23_x86_64
      cp39-cp39-manylinux_2_22_x86_64
      cp39-cp39-manylinux_2_21_x86_64
      cp39-cp39-manylinux_2_20_x86_64
      cp39-cp39-manylinux_2_19_x86_64
      cp39-cp39-manylinux_2_18_x86_64
      cp39-cp39-manylinux_2_17_x86_64
    ```

      将包的名字修改为 draftretriever-0.1.0-cp39-cp39-manylinux\_**2_31**_x86_64.whl, 安装成功 : 

    ```
    Looking in indexes: https://pypi.org/simple, https://pypi.ngc.nvidia.com
    Processing ./wheels/draftretriever-0.1.0-cp39-cp39-manylinux_2_31_x86_64.whl
    Installing collected packages: draftretriever
    Successfully installed draftretriever-0.1.0
    ```

    